<?xml version="1.0" encoding="utf-8"?>
<testsuites>
    <testsuite errors="0" failures="1" hostname="KZYH-PC-000402.local" name="pytest" skipped="0" tests="4" time="0.068"
               timestamp="2021-02-25T00:02:23.440176">
        <testcase classname="test_cacl" name="test_add" time="0.002"/>
        <testcase classname="test_calculator.Testcalcu" name="test_add" time="0.001"/>
        <testcase classname="test_calculator.Testcalcu" name="test_div" time="0.001"/>
        <testcase classname="test_demo" name="test_answer" time="0.001">
            <failure message="assert 4 == 5&#10; +  where 4 = func(3)">def test_answer():
                &gt; assert func(3) == 5
                E assert 4 == 5
                E + where 4 = func(3)

                test_demo.py:7: AssertionError
            </failure>
        </testcase>
    </testsuite>
</testsuites>